<?xml version="1.0" ?>
<!-- =================================================================================== -->
<!-- |    This document was autogenerated by xacro from robot_arm.xacro                | -->
<!-- |    EDITING THIS FILE BY HAND IS NOT RECOMMENDED                                 | -->
<!-- =================================================================================== -->
<robot name="robot_arm">
  <!-- Material 색상 정의 -->
  <material name="black">
    <color rgba="0.0 0.0 0.0 1.0"/>
  </material>
  <material name="blue">
    <color rgba="0.0 0.0 0.8 1.0"/>
  </material>
  <material name="green">
    <color rgba="0.0 0.8 0.0 1.0"/>
  </material>
  <material name="grey">
    <color rgba="0.2 0.2 0.2 1.0"/>
  </material>
  <material name="red">
    <color rgba="0.8 0.0 0.0 1.0"/>
  </material>
  <material name="yellow">
    <color rgba="1.0 1.0 0.0 1.0"/>
  </material>
  <material name="white">
    <color rgba="1.0 1.0 1.0 1.0"/>
  </material>
  <material name="orange">
    <color rgba="1.0 0.423 0.039 1.0"/>
    <!-- 255/255, 108/255, 10/255 -->
  </material>
  <!-- 링크1의 y축 위치 -->
  <!-- 링크1의 질량 (kg) -->
  <link name="base_link"/>
  <joint name="base_joint" type="fixed">
    <origin rpy="0 0 0" xyz="0 0 0"/>
    <parent link="base_link"/>
    <child link="link0"/>
  </joint>
  <!-- 링크0 -->
  <link name="link0">
    <collision>
      <origin rpy="0.0 0.0 0.0" xyz="0 0 0.0445"/>
      <geometry>
        <box size="0.12 0.12 0.089"/>
      </geometry>
    </collision>
    <visual>
      <origin rpy="0.0 0.0 0.0" xyz="0 0.03275 0.0"/>
      <geometry>
        <mesh filename="package://model3_description/mesh/joint0.stl" scale="0.001 0.001 0.001"/>
      </geometry>
      <material name="black"/>
    </visual>
    <inertial>
      <origin rpy="0.0 0.0 0.0" xyz="0.0 0.0 0.0"/>
      <mass value="1"/>
      <inertia ixx="1.0" ixy="0.0" ixz="0.0" iyy="1.0" iyz="0.0" izz="1.0"/>
    </inertial>
  </link>
  <!-- joint0 -->
  <joint name="joint0" type="revolute">
    <parent link="link0"/>
    <child link="link1"/>
    <origin rpy="0 0 0" xyz="0 0 0.089"/>
    <axis xyz="0 0 1"/>
    <dynamics damping="0.7"/>
    <limit effort="1" lower="0" upper="4.71238898038469" velocity="4.8"/>
  </joint>
  <!-- link1 -->
  <link name="link1">
    <collision>
      <origin rpy="0 0 0" xyz="0 0 0.03"/>
      <geometry>
        <box size="0.07 0.033 0.06"/>
      </geometry>
    </collision>
    <visual>
      <origin rpy="0 0 0" xyz="0 0 0"/>
      <geometry>
        <mesh filename="package://model3_description/mesh/joint1.stl" scale="0.001 0.001 0.001"/>
      </geometry>
      <material name="green"/>
    </visual>
    <inertial>
      <origin rpy="0 0 0" xyz="0 0 0.03"/>
      <mass value="1.0"/>
      <inertia ixx="0.00039075000000000004" ixy="0.0" ixz="0.0" iyy="0.00039075000000000004" iyz="0.0" izz="0.00018150000000000002"/>
    </inertial>
  </link>
  <!-- joint1 x축 회전-->
  <joint name="joint1" type="revolute">
    <parent link="link1"/>
    <child link="link3"/>
    <origin rpy="2.35619 0 0" xyz="0 0 0.06"/>
    <axis xyz="-1 0 0"/>
    <dynamics damping="0.7"/>
    <limit effort="1" lower="0" upper="4.71238898038469" velocity="4.8"/>
  </joint>
  <!-- link3 -->
  <link name="link3">
    <collision>
      <origin rpy="0 0 0" xyz="0 0 0.047"/>
      <geometry>
        <box size="0.07 0.033 0.094"/>
      </geometry>
    </collision>
    <visual>
      <origin rpy="0 0 0" xyz="0 0 0"/>
      <geometry>
        <mesh filename="package://model3_description/mesh/joint2.stl" scale="0.001 0.001 0.001"/>
      </geometry>
      <material name="yellow"/>
    </visual>
    <inertial>
      <origin rpy="0 0 0" xyz="0 0 0"/>
      <mass value="1.0"/>
      <inertia ixx="0.0008587499999999999" ixy="0.0" ixz="0.0" iyy="0.0008587499999999999" iyz="0.0" izz="0.00018150000000000002"/>
    </inertial>
  </link>
  <!-- joint3 -->
  <joint name="joint3" type="revolute">
    <parent link="link3"/>
    <child link="link4"/>
    <origin rpy="-2.35619 0 3.141592653589793" xyz="0 0 0.094"/>
    <axis xyz="1 0 0"/>
    <dynamics damping="0.7"/>
    <limit effort="1" lower="0" upper="4.71238898038469" velocity="4.8"/>
  </joint>
  <!-- link4 -->
  <link name="link4">
    <collision>
      <origin rpy="0 0 0" xyz="0 0 0.047"/>
      <geometry>
        <box size="0.07 0.033 0.094"/>
      </geometry>
    </collision>
    <visual>
      <origin rpy="0 0 0" xyz="0 0 0"/>
      <geometry>
        <mesh filename="package://model3_description/mesh/joint2.stl" scale="0.001 0.001 0.001"/>
      </geometry>
      <material name="red"/>
    </visual>
    <inertial>
      <origin rpy="0 0 0" xyz="0 0 0"/>
      <mass value="1.0"/>
      <inertia ixx="0.0008587499999999999" ixy="0.0" ixz="0.0" iyy="0.0008587499999999999" iyz="0.0" izz="0.00018150000000000002"/>
    </inertial>
  </link>
  <!-- joint4-->
  <joint name="joint4" type="revolute">
    <parent link="link4"/>
    <child link="link5"/>
    <origin rpy="2.35619 0 3.141592653589793" xyz="0 0 0.094"/>
    <axis xyz="-1 0 0"/>
    <dynamics damping="0.7"/>
    <limit effort="1" lower="0" upper="4.71238898038469" velocity="4.8"/>
  </joint>
  <!-- link5 -->
  <link name="link5">
    <collision>
      <origin rpy="0 0 0" xyz="0 0 0.0475"/>
      <geometry>
        <box size="0.07 0.033 0.095"/>
      </geometry>
    </collision>
    <visual>
      <origin rpy="0 0 0" xyz="0 0 0"/>
      <geometry>
        <mesh filename="package://model3_description/mesh/joint3.stl" scale="0.001 0.001 0.001"/>
      </geometry>
      <material name="black"/>
    </visual>
    <inertial>
      <origin rpy="0 0 0" xyz="0 0 0"/>
      <mass value="1.0"/>
      <inertia ixx="0.0008587499999999999" ixy="0.0" ixz="0.0" iyy="0.0008587499999999999" iyz="0.0" izz="0.00018150000000000002"/>
    </inertial>
  </link>
  <!-- joint5 -->
  <joint name="joint5" type="revolute">
    <parent link="link5"/>
    <child link="link6"/>
    <origin rpy="0 0 0" xyz="-0.02 0 0.095"/>
    <axis xyz="0 0 1"/>
    <dynamics damping="0.7"/>
    <limit effort="1" lower="0" upper="3.141592653589793" velocity="4.8"/>
  </joint>
  <link name="link6">
    <collision>
      <origin rpy="0 0 0" xyz="-0.0075 -0.0088 0.05165"/>
      <geometry>
        <box size="0.086 0.105 0.1033"/>
      </geometry>
    </collision>
    <visual>
      <origin rpy="0 0 0" xyz="0 0 0"/>
      <geometry>
        <mesh filename="package://model3_description/mesh/joint3.stl" scale="0.001 0.001 0.001"/>
      </geometry>
      <material name="black"/>
    </visual>
    <inertial>
      <origin rpy="0 0 0" xyz="0 0 0"/>
      <mass value="1.0"/>
      <inertia ixx="0.0008587499999999999" ixy="0.0" ixz="0.0" iyy="0.0008587499999999999" iyz="0.0" izz="0.00018150000000000002"/>
    </inertial>
  </link>
  <!-- 여기서 더미 조인트를 추가 -->
  <joint name="dummy_joint" type="continuous">
    <origin rpy="0 0 0" xyz="0 0 0"/>
    <parent link="link6"/>
    <child link="dummy_link"/>
    <dynamics damping="0.7"/>
    <limit effort="0" lower="0.001" upper="0.001" velocity="0.001"/>
  </joint>
  <link name="dummy_link">
    <!-- 더미 링크는 별도의 물리적 특성을 가지지 않도록 설정 -->
    <collision>
      <origin rpy="0 0 0" xyz="0 0 0"/>
      <geometry>
        <box size="0.001 0.001 0.001"/>
      </geometry>
    </collision>
    <visual>
      <origin rpy="0 0 0" xyz="0 0 0"/>
      <geometry>
        <box size="0.001 0.001 0.001"/>
      </geometry>
    </visual>
    <inertial>
      <origin rpy="0 0 0" xyz="0 0 0"/>
      <mass value="0.0001"/>
      <inertia ixx="0.0001" ixy="0" ixz="0" iyy="0.0001" iyz="0" izz="0.0001"/>
    </inertial>
  </link>
  <!-- 기존 fixed joint로 end_link 연결 -->
  <joint name="joint6" type="fixed">
    <origin rpy="0 0 0" xyz="0 0.069 0.1033"/>
    <parent link="dummy_link"/>
    <child link="end_link"/>
  </joint>
  <link name="end_link"/>
</robot>
